<?xml version="1.0" encoding="utf-8"?>
<!-- =================================================================================== -->
<!-- |    This document was autogenerated by xacro from jackal.urdf.xacro              | -->
<!-- |    EDITING THIS FILE BY HAND IS NOT RECOMMENDED                                 | -->
<!-- =================================================================================== -->
<robot name="jackal">
  <material name="dark_grey">
    <color rgba="0.2 0.2 0.2 1.0"/>
  </material>
  <material name="light_grey">
    <color rgba="0.4 0.4 0.4 1.0"/>
  </material>
  <material name="yellow">
    <color rgba="0.8 0.8 0.0 1.0"/>
  </material>
  <material name="black">
    <color rgba="0.15 0.15 0.15 1.0"/>
  </material>
  <material name="white">
    <color rgba="1.0 1.0 1.0 1.0"/>
  </material>
  <material name="blue">
    <color rgba="0.0 0.0 0.8 1.0"/>
  </material>
  <material name="aluminium">
    <color rgba="0.64 0.65 0.66 1.0"/>
  </material>

  <link name="front_left_wheel_link">
    <visual>
      <origin rpy="1.57079632679 0 0" xyz="0 0 0"/>
      <geometry>
        <mesh filename="assets/jackal/meshes/jackal-wheel.stl"/>
      </geometry>
      <material name="black"/>
    </visual>
    <collision>
      <origin rpy="1.57079632679 0 0" xyz="0 0 0"/>
      <geometry>
        <cylinder length="0.04" radius="0.095"/>
      </geometry>
    </collision>
    <inertial>
      <origin rpy="0 0 0" xyz="0 0 0"/>
      <mass value="0.477"/>
      <inertia ixx="0.0013" ixy="0" ixz="0" iyy="0.0024" iyz="0" izz="0.0013"/>
    </inertial>
  </link>
  <gazebo reference="front_left_wheel_link">
    <material>Gazebo/DarkGrey</material>
    <selfCollide>false</selfCollide>
    <mu1 value="0.5"/>
    <mu2 value="0.5"/>
    <kp value="10000000.0"/>
    <kd value="1"/>
    <fdir1 value="1 0 0"/>
  </gazebo>
  <joint name="front_left_wheel" type="continuous">
    <parent link="chassis_link"/>
    <child link="front_left_wheel_link"/>
    <origin rpy="0 0 0" xyz="0.131 0.187795 0.0345"/>
    <axis xyz="0 1 0"/>
  </joint>
  <!-- In reality, Jackal has only two motors, one per side. However, it's more
         straightforward for Gazebo to simulate as if there's an actuator per wheel. -->
  <transmission name="front_left_wheel_trans">
    <type>transmission_interface/SimpleTransmission</type>
    <joint name="front_left_wheel">
      <hardwareInterface>hardware_interface/VelocityJointInterface</hardwareInterface>
    </joint>
    <actuator name="front_left_actuator">
      <mechanicalReduction>1</mechanicalReduction>
    </actuator>
  </transmission>
  <link name="front_right_wheel_link">
    <visual>
      <origin rpy="1.57079632679 0 0" xyz="0 0 0"/>
      <geometry>
        <mesh filename="assets/jackal/meshes/jackal-wheel.stl"/>
      </geometry>
      <material name="black"/>
    </visual>
    <collision>
      <origin rpy="1.57079632679 0 0" xyz="0 0 0"/>
      <geometry>
        <cylinder length="0.04" radius="0.095"/>
      </geometry>
    </collision>
    <inertial>
      <origin rpy="0 0 0" xyz="0 0 0"/>
      <mass value="0.477"/>
      <inertia ixx="0.0013" ixy="0" ixz="0" iyy="0.0024" iyz="0" izz="0.0013"/>
    </inertial>
  </link>
  <gazebo reference="front_right_wheel_link">
    <material>Gazebo/DarkGrey</material>
    <selfCollide>false</selfCollide>
    <mu1 value="0.5"/>
    <mu2 value="0.5"/>
    <kp value="10000000.0"/>
    <kd value="1"/>
    <fdir1 value="1 0 0"/>
  </gazebo>
  <joint name="front_right_wheel" type="continuous">
    <parent link="chassis_link"/>
    <child link="front_right_wheel_link"/>
    <origin rpy="0 0 0" xyz="0.131 -0.187795 0.0345"/>
    <axis xyz="0 1 0"/>
  </joint>
  <!-- In reality, Jackal has only two motors, one per side. However, it's more
         straightforward for Gazebo to simulate as if there's an actuator per wheel. -->
  <transmission name="front_right_wheel_trans">
    <type>transmission_interface/SimpleTransmission</type>
    <joint name="front_right_wheel">
      <hardwareInterface>hardware_interface/VelocityJointInterface</hardwareInterface>
    </joint>
    <actuator name="front_right_actuator">
      <mechanicalReduction>1</mechanicalReduction>
    </actuator>
  </transmission>
  <link name="rear_left_wheel_link">
    <visual>
      <origin rpy="1.57079632679 0 0" xyz="0 0 0"/>
      <geometry>
        <mesh filename="assets/jackal/meshes/jackal-wheel.stl"/>
      </geometry>
      <material name="black"/>
    </visual>
    <collision>
      <origin rpy="1.57079632679 0 0" xyz="0 0 0"/>
      <geometry>
        <cylinder length="0.04" radius="0.095"/>
      </geometry>
    </collision>
    <inertial>
      <origin rpy="0 0 0" xyz="0 0 0"/>
      <mass value="0.477"/>
      <inertia ixx="0.0013" ixy="0" ixz="0" iyy="0.0024" iyz="0" izz="0.0013"/>
    </inertial>
  </link>
  <gazebo reference="rear_left_wheel_link">
    <material>Gazebo/DarkGrey</material>
    <selfCollide>false</selfCollide>
    <mu1 value="0.5"/>
    <mu2 value="0.5"/>
    <kp value="10000000.0"/>
    <kd value="1"/>
    <fdir1 value="1 0 0"/>
  </gazebo>
  <joint name="rear_left_wheel" type="continuous">
    <parent link="chassis_link"/>
    <child link="rear_left_wheel_link"/>
    <origin rpy="0 0 0" xyz="-0.131 0.187795 0.0345"/>
    <axis xyz="0 1 0"/>
  </joint>
  <!-- In reality, Jackal has only two motors, one per side. However, it's more
         straightforward for Gazebo to simulate as if there's an actuator per wheel. -->
  <transmission name="rear_left_wheel_trans">
    <type>transmission_interface/SimpleTransmission</type>
    <joint name="rear_left_wheel">
      <hardwareInterface>hardware_interface/VelocityJointInterface</hardwareInterface>
    </joint>
    <actuator name="rear_left_actuator">
      <mechanicalReduction>1</mechanicalReduction>
    </actuator>
  </transmission>
  <link name="rear_right_wheel_link">
    <visual>
      <origin rpy="1.57079632679 0 0" xyz="0 0 0"/>
      <geometry>
        <mesh filename="assets/jackal/meshes/jackal-wheel.stl"/>
      </geometry>
      <material name="black"/>
    </visual>
    <collision>
      <origin rpy="1.57079632679 0 0" xyz="0 0 0"/>
      <geometry>
        <cylinder length="0.04" radius="0.095"/>
      </geometry>
    </collision>
    <inertial>
      <origin rpy="0 0 0" xyz="0 0 0"/>
      <mass value="0.477"/>
      <inertia ixx="0.0013" ixy="0" ixz="0" iyy="0.0024" iyz="0" izz="0.0013"/>
    </inertial>
  </link>
  <gazebo reference="rear_right_wheel_link">
    <material>Gazebo/DarkGrey</material>
    <selfCollide>false</selfCollide>
    <mu1 value="0.5"/>
    <mu2 value="0.5"/>
    <kp value="10000000.0"/>
    <kd value="1"/>
    <fdir1 value="1 0 0"/>
  </gazebo>
  <joint name="rear_right_wheel" type="continuous">
    <parent link="chassis_link"/>
    <child link="rear_right_wheel_link"/>
    <origin rpy="0 0 0" xyz="-0.131 -0.187795 0.0345"/>
    <axis xyz="0 1 0"/>
  </joint>
  <!-- In reality, Jackal has only two motors, one per side. However, it's more
         straightforward for Gazebo to simulate as if there's an actuator per wheel. -->
  <transmission name="rear_right_wheel_trans">
    <type>transmission_interface/SimpleTransmission</type>
    <joint name="rear_right_wheel">
      <hardwareInterface>hardware_interface/VelocityJointInterface</hardwareInterface>
    </joint>
    <actuator name="rear_right_actuator">
      <mechanicalReduction>1</mechanicalReduction>
    </actuator>
  </transmission>
  <link name="base_link"/>
  <joint name="base_link_joint" type="fixed">
    <origin rpy="0 0 0" xyz="0 0 0"/>
    <parent link="base_link"/>
    <child link="chassis_link"/>
  </joint>
  <link name="chassis_link">
    <visual>
      <origin rpy="1.57079632679 0 1.57079632679" xyz="0 0 -0.0655"/>
      <geometry>
        <mesh filename="assets/jackal/meshes/jackal-base.stl"/>
      </geometry>
      <material name="dark_grey"/>
    </visual>
    <collision>
      <origin xyz="0 0 0.092"/>
      <geometry>
        <box size="0.42 0.31 0.184"/>
      </geometry>
    </collision>
    <inertial>
      <!-- Center of mass -->
      <origin rpy="0 0 0" xyz="0.012  0.002 0.067"/>
      <mass value="16.523"/>
      <!-- Moments of inertia: ( chassis without wheels ) -->
      <inertia ixx="0.3136" ixy="-0.0008" ixz="0.0164" iyy="0.3922" iyz="-0.0009" izz="0.4485"/>
    </inertial>
  </link>
  <link name="front_fender_link">
    <visual>
      <geometry>
        <mesh filename="assets/jackal/meshes/jackal-fender.stl"/>
      </geometry>
      <material name="yellow"/>
    </visual>
    <collision>
      <geometry>
        <mesh filename="assets/jackal/meshes/jackal-fender.stl"/>
      </geometry>
    </collision>
  </link>
  <joint name="front_fender_joint" type="fixed">
    <origin rpy="0 0 0" xyz="0 0 0"/>
    <parent link="chassis_link"/>
    <child link="front_fender_link"/>
  </joint>
  <link name="rear_fender_link">
    <visual>
      <geometry>
        <mesh filename="assets/jackal/meshes/jackal-fender.stl"/>
      </geometry>
      <material name="yellow"/>
    </visual>
    <collision>
      <geometry>
        <mesh filename="assets/jackal/meshes/jackal-fender.stl"/>
      </geometry>
    </collision>
  </link>
  <joint name="rear_fender_joint" type="fixed">
    <origin rpy="0 0 3.14159265359" xyz="0 0 0"/>
    <parent link="chassis_link"/>
    <child link="rear_fender_link"/>
  </joint>
  <!-- Default Internal IMU Link -->
  <link name="imu_link">
    <inertial>
      <mass value="0.001"/>
      <origin rpy="0 0 0" xyz="0 0 0"/>
      <inertia ixx="1e-09" ixy="0.0" ixz="0.0" iyy="1e-09" iyz="0.0" izz="1e-09"/>
    </inertial>
  </link>
  <joint name="imu_joint" type="fixed">
    <parent link="chassis_link"/>
    <child link="imu_link"/>
  </joint>
  <!-- Default NAVSAT Link -->
  <link name="navsat_link">
    <visual>
      <geometry>
        <cylinder length="0.016" radius="0.026"/>
      </geometry>
      <origin xyz="0 0 0.008"/>
      <material name="black"/>
    </visual>
  </link>
  <joint name="navsat_joint" type="fixed">
    <parent link="chassis_link"/>
    <child link="navsat_link"/>
    <origin xyz="-0.180 0.126 0.1815"/>
  </joint>
  <link name="mid_mount"/>
  <link name="rear_mount"/>
  <joint name="rear_mount_joint" type="fixed">
    <parent link="mid_mount"/>
    <child link="rear_mount"/>
    <origin xyz="-0.12 0 0"/>
  </joint>
  <link name="front_mount"/>
  <joint name="front_mount_joint" type="fixed">
    <parent link="mid_mount"/>
    <child link="front_mount"/>
    <origin xyz="0.12 0 0"/>
  </joint>

  <gazebo reference="base_link">
    <turnGravityOff>false</turnGravityOff>
  </gazebo>
  <gazebo reference="chassis_link">
    <material>Gazebo/DarkGrey</material>
    <turnGravityOff>false</turnGravityOff>
  </gazebo>
  <gazebo reference="imu_link">
    <turnGravityOff>false</turnGravityOff>
  </gazebo>
  <gazebo reference="navsat_link">
    <material>Gazebo/DarkGrey</material>
    <turnGravityOff>false</turnGravityOff>
  </gazebo>
  <gazebo reference="front_fender_link">
    <material>Gazebo/Yellow</material>
    <turnGravityOff>false</turnGravityOff>
  </gazebo>
  <gazebo reference="rear_fender_link">
    <material>Gazebo/Yellow</material>
    <turnGravityOff>false</turnGravityOff>
  </gazebo>

  <!-- velodyne 16 -->
  <joint name="VLP16_base_mount_joint" type="fixed">
    <parent link="JACKAL_LASER_3D_vlp16_plate"/>
    <child link="VLP16_base_link"/>
    <origin rpy="0 0 0" xyz="0 0 0"/>
  </joint>
  <link name="VLP16_base_link">
    <inertial>
      <mass value="0.1"/>
      <origin xyz="0 0 0"/>
      <inertia ixx="0.1" ixy="0" ixz="0" iyy="0.1" iyz="0" izz="0.1"/>
    </inertial>
    <visual>
      <geometry>
        <mesh filename="assets/jackal/meshes/VLP16_base_1.stl" />
      </geometry>
      <material name="light_grey"/>
    </visual>
    <visual>
      <geometry>
        <mesh filename="assets/jackal/meshes/VLP16_base_2.stl" />
      </geometry>
      <material name="light_grey"/>
    </visual>
    <collision>
      <origin rpy="0 0 0" xyz="0 0 0.03585"/>
      <geometry>
        <cylinder radius="0.0516" length="0.0717"/>
      </geometry>
    </collision>
  </link>
  <joint name="VLP16_base_scan_joint" type="fixed" >
    <origin xyz="0 0 0.0377" rpy="0 0 0" />
    <parent link="VLP16_base_link" />
    <child link="VLP16"/>
  </joint>
  <link name="VLP16">
    <inertial>
      <mass value="0.1"/>
      <origin xyz="0 0 0"/>
      <inertia ixx="0.1" ixy="0" ixz="0" iyy="0.1" iyz="0" izz="0.1"/>
    </inertial>
    <visual>
      <origin xyz="0 0 -0.0377" />
      <geometry>
        <mesh filename="assets/jackal/meshes/VLP16_scan.stl" />
      </geometry>
      <material name="blue"/>
    </visual>
  </link>
  <joint name="mid_mount_joint" type="fixed">
    <parent link="chassis_link" />
    <child link="mid_mount" />
    <origin xyz="0 0 0.184" />
  </joint>
  <joint name="JACKAL_LASER_3D_vlp16_mount_joint" type="fixed">
    <parent link="mid_mount" />
    <child link="JACKAL_LASER_3D_vlp16_mount" />
    <origin xyz="0 0 0" rpy="0 0 0" />
  </joint>
  <link name="JACKAL_LASER_3D_vlp16_mount" />
  <joint name="JACKAL_LASER_3D_vlp16_leg1_joint" type="fixed">
    <parent link="JACKAL_LASER_3D_vlp16_mount" />
    <child link="JACKAL_LASER_3D_vlp16_leg1" />
    <origin xyz="0.05 0.05 0" rpy="0 0 0" />
  </joint>
  <link name="JACKAL_LASER_3D_vlp16_leg1">
    <visual>
      <geometry>
        <cylinder length="0.1" radius="0.003" />
      </geometry>
      <material name="black" />
      <origin xyz="0 0 0.05" rpy="0 0 0" />
    </visual>
    <collision>
      <geometry>
        <cylinder length="0.1" radius="0.003" />
      </geometry>
      <origin xyz="0 0 0.05" rpy="0 0 0" />
    </collision>
  </link>
  <joint name="JACKAL_LASER_3D_vlp16_leg2_joint" type="fixed">
    <parent link="JACKAL_LASER_3D_vlp16_mount" />
    <child link="JACKAL_LASER_3D_vlp16_leg2" />
    <origin xyz="0.05 -0.05 0" rpy="0 0 0" />
  </joint>
  <link name="JACKAL_LASER_3D_vlp16_leg2">
    <visual>
      <geometry>
        <cylinder length="0.1" radius="0.003" />
      </geometry>
      <material name="black" />
      <origin xyz="0 0 0.05" rpy="0 0 0" />
    </visual>
    <collision>
      <geometry>
        <cylinder length="0.1" radius="0.003" />
      </geometry>
      <origin xyz="0 0 0.05" rpy="0 0 0" />
    </collision>
  </link>
  <joint name="JACKAL_LASER_3D_vlp16_leg3_joint" type="fixed">
    <parent link="JACKAL_LASER_3D_vlp16_mount" />
    <child link="JACKAL_LASER_3D_vlp16_leg3" />
    <origin xyz="-0.05 0.05 0" rpy="0 0 0" />
  </joint>
  <link name="JACKAL_LASER_3D_vlp16_leg3">
    <visual>
      <geometry>
        <cylinder length="0.1" radius="0.003" />
      </geometry>
      <material name="black" />
      <origin xyz="0 0 0.05" rpy="0 0 0" />
    </visual>
    <collision>
      <geometry>
        <cylinder length="0.1" radius="0.003" />
      </geometry>
      <origin xyz="0 0 0.05" rpy="0 0 0" />
    </collision>
  </link>
  <joint name="JACKAL_LASER_3D_vlp16_leg4_joint" type="fixed">
    <parent link="JACKAL_LASER_3D_vlp16_mount" />
    <child link="JACKAL_LASER_3D_vlp16_leg4" />
    <origin xyz="-0.05 -0.05 0" rpy="0 0 0" />
  </joint>
  <link name="JACKAL_LASER_3D_vlp16_leg4">
    <visual>
      <geometry>
        <cylinder length="0.1" radius="0.003" />
      </geometry>
      <material name="black" />
      <origin xyz="0 0 0.05" rpy="0 0 0" />
    </visual>
    <collision>
      <geometry>
        <cylinder length="0.1" radius="0.003" />
      </geometry>
      <origin xyz="0 0 0.05" rpy="0 0 0" />
    </collision>
  </link>
  <joint name="JACKAL_LASER_3D_vlp16_plate_joint" type="fixed">
    <parent link="JACKAL_LASER_3D_vlp16_mount" />
    <child link="JACKAL_LASER_3D_vlp16_plate" />
    <origin xyz="0 0 0.1" rpy="0 0 0" />
  </joint>
  <link name="JACKAL_LASER_3D_vlp16_plate">
    <visual>
      <geometry>
        <box size="0.1 0.1 0.002" />
      </geometry>
      <material name="black" />
      <origin xyz="0 0 -0.001" rpy="0 0 0" />
    </visual>
    <collision>
      <geometry>
        <box size="0.1 0.1 0.002" />
      </geometry>
      <origin xyz="0 0 -0.001" rpy="0 0 0" />
    </collision>
  </link>

  <!-- D435i -->
  <joint name="JACKAL_STEREO_d435_joint" type="fixed">
    <parent link="base_link" /> <!-- base_link = chassis_link -->
    <child link="JACKAL_STEREO_d435_camera" />
    <origin xyz="0.215 0 0.225" rpy="1.57079632679 0 1.57079632679" />
  </joint>
  <link name="JACKAL_STEREO_d435_camera">
    <visual>
      <geometry>
        <mesh filename="assets/jackal/meshes/d435.stl" />
      </geometry>
    </visual>
    <collision>
      <origin xyz="0 0 0" rpy="0 0 0"/>
      <geometry>
        <mesh filename="assets/jackal/meshes/d435.stl" />
      </geometry>
    </collision>
    <inertial>
      <!-- The following are not reliable values, and should not be used for modeling -->
      <mass value="0.072" />
      <origin xyz="0 0 0" />
      <inertia ixx="0.003881243" ixy="0.0" ixz="0.0" iyy="0.000498940" iyz="0.0" izz="0.003879257" />
    </inertial>
  </link>

  <!-- T265 -->
  <joint name="JACKAL_STEREO_t265_joint" type="fixed">
    <parent link="base_link" /> <!-- base_link = chassis_link -->
    <child link="JACKAL_STEREO_t265_camera" />
    <origin xyz="0.2 0 0.2" rpy="1.57079632679 0 1.57079632679" />
  </joint>
  <link name="JACKAL_STEREO_t265_camera">
    <visual>
      <geometry>
        <mesh filename="assets/jackal/meshes/t265.stl" />
      </geometry>
    </visual>
    <collision>
      <origin xyz="0 0 0" rpy="0 0 0"/>
      <geometry>
        <mesh filename="assets/jackal/meshes/t265.stl" />
      </geometry>
    </collision>
    <inertial>
      <!-- The following are not reliable values, and should not be used for modeling -->
      <mass value="0.068024" />
      <origin xyz="0 0 0" />
      <inertia ixx="0.0000039782" ixy="0.0" ixz="0.000000034641" iyy="0.000065045" iyz="0.0" izz="0.000067499" />
    </inertial>
  </link>

  <!--
    As you add to this URDF, please be aware that both the robot and
    simulation include it. You must retain compatibility with all of
    the following launch files:

    jackal_viz/launch/view_model.launch
    jackal_gazebo/launch/jackal_world.launch
    jackal_base/launch/base.launch
  -->
  <!-- 
    Add Cameras. 
    - JACKAL_FLEA3
    - JACKAL_STEREO_FLEA3
    - JACKAL_BB2
  -->
  <!-- This file is a placeholder which is included by default from
       jackal.urdf.xacro. If a robot is being customized and requires
       additional URDF, set the JACKAL_URDF_EXTRAS environment variable
       to the full path of the file you would like included. -->
  <!-- This file is a placeholder which is included by default from
       jackal.urdf.xacro. If a robot is being customized and requires
       additional URDF, set the JACKAL_URDF_EXTRAS environment variable
       to the full path of the file you would like included. -->
</robot>
